<?xml version="1.0" encoding="UTF-8"?>
<testng-results skipped="0" failed="3" total="3" passed="0">
  <reporter-output>
  </reporter-output>
  <suite name="Default suite" duration-ms="830" started-at="2016-05-25T09:19:11Z" finished-at="2016-05-25T09:19:12Z">
    <groups>
    </groups>
    <test name="Default test" duration-ms="830" started-at="2016-05-25T09:19:11Z" finished-at="2016-05-25T09:19:12Z">
      <class name="com.study.suit.SunTest">
        <test-method status="FAIL" signature="login(java.lang.String, java.lang.String)[pri:0, instance:com.study.suit.SunTest@4c75cab9]" name="login" duration-ms="549" started-at="2016-05-25T17:19:11Z" data-provider="signup" finished-at="2016-05-25T17:19:12Z">
          <params>
            <param index="0">
              <value>
                <![CDATA[15015431222]]>
              </value>
            </param>
            <param index="1">
              <value>
                <![CDATA[123456]]>
              </value>
            </param>
          </params>
          <exception class="java.lang.AssertionError">
            <message>
              <![CDATA[error expected [ok] but found [error]]]>
            </message>
            <full-stacktrace>
              <![CDATA[java.lang.AssertionError: error expected [ok] but found [error]
	at org.testng.Assert.fail(Assert.java:94)
	at org.testng.Assert.failNotEquals(Assert.java:496)
	at org.testng.Assert.assertEquals(Assert.java:125)
	at com.study.suit.SunTest.login(SunTest.java:19)
	at sun.reflect.NativeMethodAccessorImpl.invoke0(Native Method)
	at sun.reflect.NativeMethodAccessorImpl.invoke(Unknown Source)
	at sun.reflect.DelegatingMethodAccessorImpl.invoke(Unknown Source)
	at java.lang.reflect.Method.invoke(Unknown Source)
	at org.testng.internal.MethodInvocationHelper.invokeMethod(MethodInvocationHelper.java:85)
	at org.testng.internal.Invoker.invokeMethod(Invoker.java:639)
	at org.testng.internal.Invoker.invokeTestMethod(Invoker.java:821)
	at org.testng.internal.Invoker.invokeTestMethods(Invoker.java:1131)
	at org.testng.internal.TestMethodWorker.invokeTestMethods(TestMethodWorker.java:124)
	at org.testng.internal.TestMethodWorker.run(TestMethodWorker.java:108)
	at org.testng.TestRunner.privateRun(TestRunner.java:773)
	at org.testng.TestRunner.run(TestRunner.java:623)
	at org.testng.SuiteRunner.runTest(SuiteRunner.java:357)
	at org.testng.SuiteRunner.runSequentially(SuiteRunner.java:352)
	at org.testng.SuiteRunner.privateRun(SuiteRunner.java:310)
	at org.testng.SuiteRunner.run(SuiteRunner.java:259)
	at org.testng.SuiteRunnerWorker.runSuite(SuiteRunnerWorker.java:52)
	at org.testng.SuiteRunnerWorker.run(SuiteRunnerWorker.java:86)
	at org.testng.TestNG.runSuitesSequentially(TestNG.java:1185)
	at org.testng.TestNG.runSuitesLocally(TestNG.java:1110)
	at org.testng.TestNG.run(TestNG.java:1018)
	at org.testng.remote.RemoteTestNG.run(RemoteTestNG.java:111)
	at org.testng.remote.RemoteTestNG.initAndRun(RemoteTestNG.java:204)
	at org.testng.remote.RemoteTestNG.main(RemoteTestNG.java:175)
]]>
            </full-stacktrace>
          </exception> <!-- java.lang.AssertionError -->
          <reporter-output>
          </reporter-output>
        </test-method> <!-- login -->
        <test-method status="FAIL" signature="login(java.lang.String, java.lang.String)[pri:0, instance:com.study.suit.SunTest@4c75cab9]" name="login" duration-ms="125" started-at="2016-05-25T17:19:12Z" data-provider="signup" finished-at="2016-05-25T17:19:12Z">
          <params>
            <param index="0">
              <value>
                <![CDATA[13611901234]]>
              </value>
            </param>
            <param index="1">
              <value>
                <![CDATA[123456]]>
              </value>
            </param>
          </params>
          <exception class="java.lang.AssertionError">
            <message>
              <![CDATA[error expected [ok] but found [error]]]>
            </message>
            <full-stacktrace>
              <![CDATA[java.lang.AssertionError: error expected [ok] but found [error]
	at org.testng.Assert.fail(Assert.java:94)
	at org.testng.Assert.failNotEquals(Assert.java:496)
	at org.testng.Assert.assertEquals(Assert.java:125)
	at com.study.suit.SunTest.login(SunTest.java:19)
	at sun.reflect.NativeMethodAccessorImpl.invoke0(Native Method)
	at sun.reflect.NativeMethodAccessorImpl.invoke(Unknown Source)
	at sun.reflect.DelegatingMethodAccessorImpl.invoke(Unknown Source)
	at java.lang.reflect.Method.invoke(Unknown Source)
	at org.testng.internal.MethodInvocationHelper.invokeMethod(MethodInvocationHelper.java:85)
	at org.testng.internal.Invoker.invokeMethod(Invoker.java:639)
	at org.testng.internal.Invoker.invokeTestMethod(Invoker.java:821)
	at org.testng.internal.Invoker.invokeTestMethods(Invoker.java:1131)
	at org.testng.internal.TestMethodWorker.invokeTestMethods(TestMethodWorker.java:124)
	at org.testng.internal.TestMethodWorker.run(TestMethodWorker.java:108)
	at org.testng.TestRunner.privateRun(TestRunner.java:773)
	at org.testng.TestRunner.run(TestRunner.java:623)
	at org.testng.SuiteRunner.runTest(SuiteRunner.java:357)
	at org.testng.SuiteRunner.runSequentially(SuiteRunner.java:352)
	at org.testng.SuiteRunner.privateRun(SuiteRunner.java:310)
	at org.testng.SuiteRunner.run(SuiteRunner.java:259)
	at org.testng.SuiteRunnerWorker.runSuite(SuiteRunnerWorker.java:52)
	at org.testng.SuiteRunnerWorker.run(SuiteRunnerWorker.java:86)
	at org.testng.TestNG.runSuitesSequentially(TestNG.java:1185)
	at org.testng.TestNG.runSuitesLocally(TestNG.java:1110)
	at org.testng.TestNG.run(TestNG.java:1018)
	at org.testng.remote.RemoteTestNG.run(RemoteTestNG.java:111)
	at org.testng.remote.RemoteTestNG.initAndRun(RemoteTestNG.java:204)
	at org.testng.remote.RemoteTestNG.main(RemoteTestNG.java:175)
]]>
            </full-stacktrace>
          </exception> <!-- java.lang.AssertionError -->
          <reporter-output>
          </reporter-output>
        </test-method> <!-- login -->
        <test-method status="FAIL" signature="login(java.lang.String, java.lang.String)[pri:0, instance:com.study.suit.SunTest@4c75cab9]" name="login" duration-ms="140" started-at="2016-05-25T17:19:12Z" data-provider="signup" finished-at="2016-05-25T17:19:12Z">
          <params>
            <param index="0">
              <value>
                <![CDATA[13588123456]]>
              </value>
            </param>
            <param index="1">
              <value>
                <![CDATA[123456]]>
              </value>
            </param>
          </params>
          <exception class="java.lang.AssertionError">
            <message>
              <![CDATA[error expected [ok] but found [error]]]>
            </message>
            <full-stacktrace>
              <![CDATA[java.lang.AssertionError: error expected [ok] but found [error]
	at org.testng.Assert.fail(Assert.java:94)
	at org.testng.Assert.failNotEquals(Assert.java:496)
	at org.testng.Assert.assertEquals(Assert.java:125)
	at com.study.suit.SunTest.login(SunTest.java:19)
	at sun.reflect.NativeMethodAccessorImpl.invoke0(Native Method)
	at sun.reflect.NativeMethodAccessorImpl.invoke(Unknown Source)
	at sun.reflect.DelegatingMethodAccessorImpl.invoke(Unknown Source)
	at java.lang.reflect.Method.invoke(Unknown Source)
	at org.testng.internal.MethodInvocationHelper.invokeMethod(MethodInvocationHelper.java:85)
	at org.testng.internal.Invoker.invokeMethod(Invoker.java:639)
	at org.testng.internal.Invoker.invokeTestMethod(Invoker.java:821)
	at org.testng.internal.Invoker.invokeTestMethods(Invoker.java:1131)
	at org.testng.internal.TestMethodWorker.invokeTestMethods(TestMethodWorker.java:124)
	at org.testng.internal.TestMethodWorker.run(TestMethodWorker.java:108)
	at org.testng.TestRunner.privateRun(TestRunner.java:773)
	at org.testng.TestRunner.run(TestRunner.java:623)
	at org.testng.SuiteRunner.runTest(SuiteRunner.java:357)
	at org.testng.SuiteRunner.runSequentially(SuiteRunner.java:352)
	at org.testng.SuiteRunner.privateRun(SuiteRunner.java:310)
	at org.testng.SuiteRunner.run(SuiteRunner.java:259)
	at org.testng.SuiteRunnerWorker.runSuite(SuiteRunnerWorker.java:52)
	at org.testng.SuiteRunnerWorker.run(SuiteRunnerWorker.java:86)
	at org.testng.TestNG.runSuitesSequentially(TestNG.java:1185)
	at org.testng.TestNG.runSuitesLocally(TestNG.java:1110)
	at org.testng.TestNG.run(TestNG.java:1018)
	at org.testng.remote.RemoteTestNG.run(RemoteTestNG.java:111)
	at org.testng.remote.RemoteTestNG.initAndRun(RemoteTestNG.java:204)
	at org.testng.remote.RemoteTestNG.main(RemoteTestNG.java:175)
]]>
            </full-stacktrace>
          </exception> <!-- java.lang.AssertionError -->
          <reporter-output>
          </reporter-output>
        </test-method> <!-- login -->
      </class> <!-- com.study.suit.SunTest -->
    </test> <!-- Default test -->
  </suite> <!-- Default suite -->
</testng-results>
